## 프로그램 오류



### 프로그램 에러 || 오류란 ?

프로그램이 실행 중 어떤 원인에 의해서 오작동을 하거나 비정상적으로 종료되는 경우가 있다. 이러한 결과를 초래하는 원인을 프로그램 에러 또는 오류라고 한다.

### 발생시점에 따라 다음과 같이 나눈다. 

> * `컴파일 에러` - 컴파일 시에 발생하는 에러
> * `런타임 에러` - 실행 시에 발생하는 에러
> * `논리적 에러` - 실행은 되지만, 의도와 다르게 동작하는 것



### 에러와 예외

컴파일하면 소스코드(`*.java`)에 대해 오타나 잘못된 구문, 자료형 체크 등의 기본적인 검사를 수행하여 오류가 있는지를 알려주고 성공적으로 컴파일을 마치면 비로소 `*.class`가 생성된다.

하지만 컴파일이 올바르게 되었다고 해서 실행 시에도 에러가 발생하지 않는 것은 아니다. 잠재적인 오류까지는 볼 수 없기 때문이다.

*런타임 에러를 방지하기 위해서는 프로그램의 실행 도중 발생할 수 있는 모든 경우의 수를 고려하여 이에 대한 대비를 해야한다.* 

자바에서는 실행 시 발생할 수 있는 프로그램 오류를 `에러`, `예외` 두 가지로 구분하였다.

| 구분                              | 에러 | 예외 |
| --------------------------------- | ---- | ---- |
| 복구할 수 있는가 ?                | X    | O    |
| 비정상적인 종료를 막을 수 있는가? | X    | O    |

> * `에러 (Error)` - 프로그램 코드에 의해서 수습될 수 없는 심각한 오류
> * `예외 (Exception)` - 프로그램 코드에 의해서 수습될 수 있는 다소 미약한 오류



### 예외 클래스의 계층구조

> 자바에서는 실행 시 발생할 수 있는 오류(`Exception`과 `Error`)를 클래스로 정의하였다.

모든 예외의 최고 조상은 Exception 클래스이며, 상속 계층도를 Exception 클래스부터 도식화하면 다음과 같다.

* `Exception`
  * `IOException`
  * `ClassNotFoundException`
  * `...`
  * `RuntimeException`
    * `ArithmeticException`
    * `ClassCastException`
    * `NullPointerException`
    * `...`
    * `IndexOutOfBoundsException`

도식화에서 볼 수 있듯, 예외 클래스들은 다음과 같이 두 그룹으로 나눠질 수 있다.

> 1. `Exception` 클래스와 그 자손들
>
>    : 주로 프로그래머의 실수에 의해서 발생될 수 있는 예외를 말한다.
>
> 2. `RuntimeException` 클래스와 그 자손들
>
>    : 외부의 영향으로 발생할 수 있는 것들로써, 프로그램의 사용자들의 동작에 의해서 발생하는 경우가 많다.



### 예외처리하기 - try - catch문

> *프로그램의 실행 도중에 발생하는 에러는 어쩔 수 없지만 예외는 프로그래머가 이에 대한 처리를 미리 해주어야 한다.*



#### 예외처리

* 정의 - 프로그램 실행 시 발생할 수 있는 예외에 대비한 코드를 작성하는 것.
* 목적 - 프로그램의 비정상 종료를 막고, 정상적인 실행상태를 유지하는 것.



발생한 예외를 처리하지 못하면 프로그램은 비정상적으로 종료되며, 처리되지 못한 예외는 JVM의 예외처리기(`UncaughtExceptionHandler`)가 받아서 화면에 출력한다.

예외를 처리하기 위해서는 `try - catch` 를 사용하며, 그 구조는 다음과 같다.

```java
try {
    예외가 발생할 가능성이 있는 문장들을 넣는다.
} catch(Exception1 e1) {
    // Exception1이 발생했을 경우, 이를 처리하기 위한 문장을 적는다.
} catch(Exception2 e2) {
    // Exception1이 발생했을 경우, 이를 처리하기 위한 문장을 적는다.
} catch(ExceptionN eN) {
    // ExceptionN이 발생했을 경우, 이를 처리하기 위한 문장을 적는다.
} 
```

> 하나의 try 블럭 다음에는 여러 종류의 예외를 처리할 수 있도록 하나 이상의 catch 블럭이 올 수 있으며, 이 중 발생한 예외의 종류와 일치하는 단 한 개의 catch 블럭만 수행된다. 발생한 예외의 종류와 일치하는 catch블럭이 없으면 예외는 처리되지 않는다.



* 예제 - 다중 `try - catch`문의 사용법 

```java
class Exception1 {
    public static void main(String[] args) {
        try {
            try {
            } catch (Exception e) {
            }
        } catch(Exception e) {
            try {
            } catch (Exception e) {
            }
        }
        
        try {
        } catch (Excepion e) {
            
        } // try-catch의 끝
    } // main 메서드의 끝
}
```

위처럼 여러 개의 `try-catch`문이 사용될 수 있으며, `try`블럭 또는 `catch` 블럭에 또 다른 `try-catch`문이 포함될 수 있다. 



### try - catch 문에서의 흐름

`try - catch`문에서 예외가 발생했을 때와, 발생하지 않았을 때의 흐름을 알아보자

>   *   try 블럭 내에서 예외가 발생한 경우
>       1.   발생한 예외와 일치하는 예외가 catch문에서 있는지 확인한다.
>       2.   일치하는 catch 블럭을 찾게 되면, 그 catch 블럭의 문장들을 수행하고 전체 `try - catch`문을 빠져나가서 그 다음 문장을 수행한다. 일치하는 예외가 catch에 없으면 예외는 처리되지 않는다.
>   *   try 블럭 내에서 예외가 발생하지 않은 경우
>       1.   catch 블럭을 거치지 않고 `try - catch`문을 빠져나가서 그 다음 문장들을 수행한다.

*   예제

```java
package exception;

public class ExceptionEx1 {
    public static void main(String[] args) {
        System.out.println(1);
        System.out.println(2);

        try {
            System.out.println(3);
            System.out.println(4);
        } catch (Exception e) {
            System.out.println(5);
        } // try - catch 끝
        System.out.println(6);
    } // main 끝
}
```

예외가 발생하지 않아 catch 블럭을 실행하지 않는다. 예외를 발생시켜 보자.

```java
package exception;

public class ExceptionEx2 {
    public static void main(String[] args) {
        System.out.println(1);
        System.out.println(2);
        try {
            System.out.println(3);
            System.out.println(0 / 0);
            System.out.println(4);
        } catch (ArithmeticException e) {
            System.out.println(5);
        } // try - catch 끝
        System.out.println(6);
    } // main 끝
}
```

결과는 1,2,3,5,6으로 `System.out.println(0/0)`에서 catch로 넘어가 `System.out.println(4)`는 수행되지 않는다. 그 다음엔 전체  `try - catch`문을 벗어나서 `System.out.println(6)`을 수행한다.



### 예외의 발생과 catch 블럭

catch블럭은 `()`과 `{}`으로 나눠져 있는데 `()`에는 처리하고자 하는 예외와 같은 타입의 참조변수 하나를 선언해야 한다. 예외가 발생하면 발생한 예외에 해당하는 클래스의 인스턴스가 만들어진다. ArithmeticException이 발생하면 ArithmeticException 클래스의 인스턴스가 생성된다. 

첫 번째 catch 블럭부터 차례로 내려가면서 catch 블럭의 괄호 내에 선언된 참조변수의 종류와 생성된 예외 클래스의 인스턴스에 `instanceof` 연산자를 이용해서 검사하게 되는데 검사결과가 true인 catch 블럭을 만날 때까지 검사는 계속된다.

모든 예외 클래스는 Exception 클래스의 자손이므로 catch 블럭의 괄호에 Exception 클래스를 선언해 놓으면 어떤 종류의 예외가 발생하더라도 이 catch 블럭에 의해서 처리된다.



```java
public class ExceptionEx3 {
    public static void main(String[] args) {
        System.out.println(1);
        System.out.println(2);
        try {
            System.out.println(3);
            System.out.println(0 / 0);
            System.out.println(4);
        } catch (ArithmeticException e) {
            if (e instanceof ArithmeticException) {
                System.out.println("Arithmetic Exception");
            }
        } catch (Exception e) {
            System.out.println("Exception");
        }
        System.out.println(5);
    } // main 끝
}
```

첫 번째 검사에서 일치하는 ArithmeticException이 발생하였기 때문에 두 번째 catch 블럭은 검사하지 않게 된다. 이처럼 `try - catch`문의 마지막에 Exception 클래스 타입의 참조변수를 선언한 catch 블럭을 사용하면 어떤 종류의 예외가 발생하더라도 이 catch 블럭에 의해 처리되도록 할 수 있다.



*   printStackTrace() 와 getMessage()

>   *   printStackTrace() - 예외 발생 당시의 호출 스택(Call Stack)에 있었던 메서드의 정보와 예외 메시지를 화면에 출력한다.
>   *   getMessage() - 발생한 예외클래스의 인스턴스에 저장된 메시지를 얻을 수 있다.

printStackTrace()를 사용해서 호출 스택에 대한 정보와 예외 메시지를 출력하여 예외가 발생해도 비정상적으로 종료하지 않도록 해주는 동시에 printStackTrace() 또는 getMessage()를 통해서 예외의 발생원인을 알 수 있다.



*   멀티 catch 블럭

>   JDK 1.7부터 여러 catch 블럭을 `|`기호를 이용해서 하나의 catch 블럭으로 합칠 수 있게 되었으며 이를 멀티 catch 블럭이라고 한다.
>
>   *`|`로 연결할 수 있는 예외클래스의 개수에는 제한이 없다.*

만일 멀티 catch 블럭의 `|`기호로 연결된 예외 클래스가 서로 조상과 자손의 관계에 있다면 컴파일 에러가 발생한다.

>   왜?
>
>   두 예외 클래스가 조상과 자손의 관계에 있다면 그냥 조상 클래스만 써주는 것과 똑같기 때문이다. 불필요한 코드는 제거하라는 의미에서 에러가 발생한다.

그리고 멀티 catch는 하나의 catch 블럭으로 여러 예외를 처리하는 것이기 때문에 발생한 예외를 멀티 catch 블럭으로 처리하게 되었을 때 멀티 catch 블럭 내에서는 실제로 어떤 예외가 발생한 것인지 알 수 없다. 그래서 참조변수로 멀티 catch 블럭에 `|` 기호로 연결된 예외 클래스들의 공통 분모인 조상 예외 클래스에 선언된 멤버만 사용할 수 있다.



```java
try {
    ...
} catch (ExceptionA | ExceptionB e) {
    e.methodA();	// Error, ExceptionA에 선언된 methodA() 호출 불가
    
    if(e instanceof ExceptionA) {
        ExceptionA el = (ExceptionA) e;
        e.methodA();	// OK, ExceptionA에 선언된 메소드 호출 가능
    } else { // ExceptionB
      ...   
    }
}
```

필요하다면 위와 같이 `instanceof` 키워드를 사용하여 어떤 예외가 발생한 것인지 확인하고 개별적 처리는 가능하다. (이렇게까지 할 일은 많이 없을 것이다.)



### 예외 발생시키기

>   *키워드 throw를 사용해서 프로그래머가 고의로 예외를 발생시킬 수 있으며 방법은 아래의 순서를 따르면 된다.*
>
>     
>
>   1.   연산자 new를 이용해서 발생시키려는 예외 클래스의 객체를 만든다.
>
>        Exception e =  new Exception("Message");
>
>   2.   키워드 throw를 이용해서 예외를 발생시킨다.
>
>        throw e;



컴파일러가 예외처리를 확인하지 않는 RuntimeException 클래스들은 unchecked 예외라고 부르며, 예외처리를 확인하는 Exception 클래스들은 checked 에외 라고 부른다.



### 메서드에 예외 선언하기

>   메서드에 예외를 선언하려면, 메서드의 선언부에 키워드 throws 사용해서 메서드 내에서 발생할 수 있는 예외를 적어주기만 하면 된다. 그리고 예외가 여러 개일 경우에는 쉼표로 구분한다.

```java
void method() throws Exception1, Exception2, ... ExceptionN {
    // 메서드의 내용
}
```

최고조상인 Exception 클래스를 메서드에 선언하면 이 메서드는 모든 종류의 예외가 발생할 가능성이 있다는 뜻이다.

*   최고 조상 클래스인 Exception 클래스 메서드 throws.

```java
void method() throws Exception {
    // 메서드의 내용
}
```

메서드의 선언부에 예외를 선언함으로써 메서드를 사용하려는 사람이 메서드의 선언부를 보았을 때, 이 메서드를 사용하기 위해서는 어떤 예외들이 처리되어져야 하는지 쉽게 알 수 있다.

자바에서는 메서드를 작성할 때 메서드 내에서 발생할 가능성이 있는 예외를 메서드의 선언부에 명시하여 이 메서드를 사용하는 쪽에서는 이에 대한 처리를 하도록 강요하기 때문에 프로그래머들의 짐을 덜어주는 것은 물론이고 보다 견고한 프로그램 코드를 작성할 수 있도록 도와준다.

메서드에 예외를 선언할 때 일반적으로 RuntimeException 클래스들은 적지 않는다. 이 들을 메서드 선언부의 throws에 선언한다고 해서 문제가 되지는 않지만 보통 반드시 처리해주어야 하는 예외들만 선언한다.

*예외를 메서드의 throws에 명시하는 것은 예외를 처리하는 것이 아니다. 호출한 메서드에게 예외를 전달하여 예외처리를 떠맡기는 것이다. 이렇게 떠넘겨지는 예외는 호출스택을 따라 전달되다가 제일 마지막에 있는 main 메서드에서도 예외가 처리되지 않으면 main 메서드 마저 종료되어 프로그램 전체가 종료된다.*



*   예제

```java 
class Exception12 {
	public static void main(String[] args) throws Exception {
        method1(); // 같은 클래스내의 static 멤버이므로 객체생성없이 직접 호출가능
    } // main 끝 
    
    static void method1() throws Exception {
        method2();        
    } // method1() 끝
    
    static void method2() throws Exception {
        throw new Exception();     
    } // method2() 끝
}
```

위의 실행결과를 보면 프로그램의 실행도중 `java.lang.Exception`이 발생하여 비정상적으로 종료했다는 것과 예외가 발생했을 때 호출스택(Call Stack)의 내용을 알 수 있다. 

>   1.   예외가 발생했을 때, 모두 3개의 메서드(method1(), method2(), main())가 호출스택에 있었으며
>   2.   예외가 발생한 곳은 제일 윗줄에 있는 method2()라는 것과
>   3.   main 메서드가 method1()을 그리고, method1()은 method2()를 호출했다는 것을 알 수 있다.



`throw new Exception();` 문장에 의해 예외가 강제적으로 발생헀으나 `try - catch`로 감싸주지 않았기 때문에 method2()는 종료되면서 method1()에게 예외를 던지고, method1() 또한 예외를 main 메서드에 던진다. main 메서드 또한 예외를 처리하는 것이 아닌 단순 전달하는 것이기 때문에 비정상적으로 프로그램을 종료시킨다. 결국 어느 한 곳에서는 예외를`try - catch`로 감싸줘야 한다.



*   예제 - `try - catch`사용

```java
class ExceptionEx13 {
    public static void main(String[] args) throws Exception {
        method1();	// 같은 클래스내의 static 멤버이므로 객체 생성없이 직접 호출이 가능하다.
    } // main 끝
    
    static void method1() throws Exception {
        try {
            throw new Exception("method1 메서드에서 예외가 처리됨"); 
        } catch(Exception e) {
            e.printStackTrace();
        }
    } // method1()의 끝
}
```

```
실행결과

method1 메서드에서 예외가 처리됨.
java.lang.Exception
	at ExceptionEx13.method1(ExceptionEx13.java:8)
	at ExceptionEx13.main(ExceptionEx13.java:3)
```

예외는 처리되었지만  printSdtackTrace()를 통해 예외에 대한 정보를 화면에 출력하였따. 예외가 method1()에서 발생했으며 main메서드가  method1()을 호출했음을 알 수 있다.



### finally 블럭

>   예외 발생여부에 상관없이 실행되어야 할 코드를 포함시킬 목적으로 사용된다. `try - catch`문의 끝에 선택적으로 덧붙혀 사용할 수 있으며 `try - catch - finally`의 순서로 구성된다.

```java
try {
	// 예외가 발생할 가능성이 있는 문장들을 넣는다.
} catch (Exception e) {
    // 예외처리를 위한 문장을 적는다.
} finally {
    // 예외 발생여부에 관계없이 항상 수행되어야하는 문장들을 넣는다.
    // finally 블럭은  try - catch 맨마지막에 위치해야한다. 
}
```



### 자동 자원 반환 - try - with - resources 문

>   JDK1.7부터 `try-with-resources`문이라는 `try-catch`문의 변형이 새로 추가되었다. 이 구문은 주로 IO와 관련된 클래스를 사용할 때 유용하다.



```java
try {
    fis = new FileInputStream("score.dat");
    dis = new DataInputStream(fis);
} catch (IOException e) {
	e.printStackTrace();
} finally {
    dis.close(); 	// 작업 중에 예외가 발생하더라도 dis가 닫히도록 finally 블럭에 넣음
}
```

하지만  close()가 예외를 발생시킬 수 있다. 위의 코드는 다음과 같이 수정 되어야 한다.

```java
try {
    fis = new FileInputStream("score.dat");
    dis = new DataInputStream(fis);
} catch (IOException e) {
	e.printStackTrace();
} finally {
    try {
        if(dis != null) {
	    	dis.close(); 	// 작업 중에 예외가 발생하더라도 dis가 닫히도록 finally 블럭에 넣음                  
        }
    } catch (IOException e) {
        e.printStackTrace();
    }
}
```

코드가 복잡해져 보기에 좋지 않다. 이러한 문제를 개선하기 위해 `try - with - resources`문이 추가 되었다.

```java
// 괄호() 안에 두 문장 이상 넣을 경우 ';'로 구분한다.
try (FileInputStream fis = new FileInputStream("score.dat");
	DataInputStream dis = new DataInputStream(fis)) {
		while(true) {
            score = dis.readInt();
            System.out.println(score);
            sum += score;
        }
	} catch (EOFException e) {
    	System.out.println("점수의 총합은 " + sum + "입니다.");
	} catch (IOException ie) {
    	ie.printStackTrace();
	}
}
```

try의 `()` 괄호안에 객체를 생성하는 문장을 넣으면 이 객체는 따로 close()를 호출하지 않아도 try 블럭을 벗어나는 순간  close()된다. 그 다음에 catch 블럭 또는  finally 블럭이 수행된다. 

하지만 모든 클래스가 `try - with - resources`를 사용할 수 있는 것은 아니다. `AutoCloseable`이라는 인터페이스를 구현한 것이어야만 한다.

```java
public interface AutoCloseable {
    void close() throws Exception;
}
```

그러나 AutoCloseable 클래스에서의 close()또한 에외를 발생시킬 수 있다. 자동 호출된 close()가 예외를 발생하면 어떻게 될까 ?

```java
class TryResourceEx {
    public static void main(String[] args) {
        try (CloseableResource cr = new CloseableResource()) {
            cr.exceptionWork(false); // 예외가 발생하지 않는다.
        } catch (WorkException e) {
            e.printStackTrace();
        } catch (CloseException e) {
            e.printStackTrace();
        }
        System.out.println();
    
	    try (CloseableResource cr = new CloseableResource()) {
    	    cr.exceptionWork(true); // 예외가 발생한다.
	    } catch(WorkException e) {
    	    e.printStackTrace();
	    } catch(CloseableException e) {
        	e.printStackTrace();
    	}
	}
}

class CloseableResource implements AutoCloseable {
    public void exceptionWork(boolean exception) throws WorkException {
        System.out.println("ExceptionWork(" + exception + ")가 호출됨");
        
        if(exception) {
            throw new WorkException("WorkException 발생 !!!");
        }
    }
    
    public void close() throws CloseException {
        System.out.println("close()가 호출됨");
        throw new CloseException("CloseException 발생 !!!");
    }
}

class WorkException extends Exception {
	WorkException(String msg) {
        super(msg);
    }
}

class CloseException extends Exception {
    CloseException(String msg) {
        super(msg);
	}
}
```

main 메서드 내에서 두 개의  `try - catch`가 발생하게 되는데 두 번째 처리 과정을 살펴보면 예외가 2번 발생한다. 이 때 WorkException을 실제 발생한 예외로 두고 예외는 동시에 발생할 수는 없기 때문에CloseException은 억제된 예외로 처리된다.  억제된 에외에 대한 정보는 실제로 발생한 예외에 저장된다.

Throwable에는 억제된 예외와 관련해서 다음과 같은 메서드가 정의되어 있다.

```java
void addSuppressed(Throwable exception) // 억제된 예외를 추가
Throwable[] getSuppressed()				// 억제된 예외(배열)를 반환
```

기존의 `try - catch` 문을 사용했다면, 먼저 발생한 WorkException은 무시되고, 마지막으로 발생한 CloseException에 대한 내용만 출력되었을 것이다.



### 사용자정의 예외 만들기

>   기존에 정의된 예외 클래스 외에 필요에 따라 새로운 예외 클래스를 정의하여 사용할 수 있다.
>
>   *가능하면 새로운 예외 클래스를 만들기보다 기존의 예외클래스를 활용하자*



```java
class MyException extends Exception {
	MyException(String msg) {
        super(msg);		// 조상인 Exception 클래스의 생성자를 호출한다.
    }
}
```

필요하다면 멤버 변수나 메서드를 추가할 수 있다. Exception클래스는 생성 시에  String 값을 받아서 메시지로 저장할 수 있다.

```java
class MyException extends Exception {
    // 에러코드 값을 저장하기 위한 필드 추가
    private final int ERR_CODE;	// 생성자를 통해 초기화한다.
    
    MyException(String msg, int errCode) {
        super(msg);
        ERR_CODE = errCode;
    }
    
    MyException(String msg) {
    	this(msg, 100);		// ERR_CODE를 100으로 초기화
    }
    
    public int getErrCode() {
        return ERR_CODE;	// 이 메서드는 주로 getMessage()와 함께 사용될 것이다.
    }
}
```

요즘은 RuntimeException을 상속 받아서 예외처리를 선택적으로 할 수 있도록 하고 있다. chekced예외는 반드시 예외처리를 해주어야 하기 때문에 예외처리가 불필요한 경우에도 try-catch문을 넣어서 코드가 복잡해지기 때문이다. 그래서 필요에따라 예외처리의 여부를 선택할 수 있는 unchecked예외가 강제적인 checked예외보다 더 환영받고 있다.

```java
public class NewExceptionTest {
    public static void main(String[] args) {
        try {
            startInstall();     // 프로그램 설치에 필요한 준비를 한다.
            copyFiles();        // 파일을 복사한다.
        } catch (SpaceException e) {
            System.out.println("에러 메시지 : " + e.getMessage());
            e.printStackTrace();
            System.out.println("공간을 확보한 후에 다시 설치하시기 바랍니다.");
        } catch (MemoryException e) {
            System.out.println("에러 메시지 : " + e.getMessage());
            e.printStackTrace();
            System.gc();            // Garbage Collection을 수행하여 메모리를 늘려준다.
            System.out.println("다시 설치를 시도하세요");
        } finally {
            deleteTempFiles();      // 프로그램 설치에 사용된 임시파일을 삭제한다.
        }
    }

    void startInstall() throws SpaceException, MemoryException {
        if (!isEnoughSpace()) {       // 충분한 설치 공간이 없을 때
            throw new SpaceException("설치할 공간이 부족합니다.");
        }
        if (!isEnoughMemory()) {        // 충분한 메모리가 없을 때
            throw new MemoryException("메모리가 부족합니다.");
        }
    } // static 메서드의 끝

    static void copyFiles() { /* 파일들을 복사하는 코드를 적음 */ }

    static void deleteTempFiles() { /* 임시파일들을 삭제하는 코드를 적음 */ }

    static boolean isEnoughSpace() {
        // 설치하는데 필요한 공간이 있는지 확인하는 코드를 적음
        return false;
    }

    static boolean isEnoughMemory() {
        // 메모리가 충분한지 확인하는 코드를 적음
        return true;
    }

    class MemoryException extends Exception {
        MemoryException(String msg) {
            super(msg);
        }
    }

    class SpaceException extends Exception {
        SpaceException(String msg) {
            super(msg);
        }
    }
}
```

```
에러 메시지 : 설치할 공간이 부족합니다.
공간을 확보한 후에 다시 설치하시기 바랍니다.
exception.NewExceptionTest$SpaceException: 설치할 공간이 부족합니다.
	at exception.NewExceptionTest.startInstall(NewExceptionTest.java:24)
	at exception.NewExceptionTest.main(NewExceptionTest.java:6)
```

두 개의 사용자 정의 예외 클래스를 새로 만들어서 사용했다



### 예외 되던지기 (Exception re-throwing)

>   한 메서드에서 발생할 수 있는 예외가 여럿인 경우, 몇 개는 try - catch문을 통해서 메서드 내에서 자체적으로 처리하고 그 나머지는 선언부에 지정하여 호출한 메서드에서 처리하도록 함으로써, 양쪽에서 나눠서 처리되도록 할 수 있다. 
>
>   *단 하나의 예외에 대해서도 예외가 발생한 메서드와 호출한 메서드, 양쪽에서 처리하도록 할 수 있다. 이것은 예외를 처리한 후에 인위적으로 다시 발생시키는 방법을 통해서 가능한데 이것을 **예외 되던지기라고 한다.***

먼저, 예외가 발생할 수 있는 메서드에서 try - catch 문을 통해 내부에서 처리해주고 catch문에서 필요한 작업을 행한 뒤에 throw 문을 통해 예외를 다시 발생시킨다. 다시 발생한 예외는 메서드를 호출한 메서드에게 전달되고 호출한 메서드의  try-catch에서 또 다시 처리한다. 

**이 방법은 하나의 예외에 대해서 예외가 발생한 메서드와 이를 호출한 메서드 야쪽 모두에서 처리해줘야 할 작업이 있을 때 사용된다. 이 때 주의할 점은 예외가 발생할 메서드에서는 try-catch문을 사용해서 예외처리를 해줌과 동시에 메서드의 선언부에 발생활 예외를 throws에 지정해줘야 한다는 것이다.**

*   예제

```java
class ExceptionEx17 {
    public static void main(String[] args) {
        try {
            method1();
        } catch(Exception e) {
            System.out.println("main 메서드에서 예외가 처리되었습니다.");
        }
    }
    
    static void method1() throws Exception {
        try {
            throw new Exception();
        } catch (Exception e) {
            System.out.println("method1() 메서드에서 예외가 처리되었습니다.");
            throw e;
        }
    }
}
```

반환값이 있는  return문의 경우, catch 블럭에도 return문이 있어야 한다. 예외가 발생했을 경우에도 값을 반환해야 하기 때문이다. 

```java
static int method1() {
    try {
        System.out.println("method1()이 호출되었습니다.");
        return 0;
    } catch (Exception e) {
        e.printStackTrace();
        retrun 1;
    } finally {
        System.out.println("method1()의 finally 블럭이 실행되었습니다.");
    }
}
```

또는  catch 블럭에서 예외 되던지기를 해서 호출한 메서드로 예외를 전달하면 return 문이 없어도 된다. 그래서 검증에서도 assert 대신 AssertError를 생성해서 던진다.

```java
static int method1() {
    try {
        System.out.println("method1()이 호출되었습니다.");
        return 0;
    } catch (Exception e) {
        e.printStackTrace();
        throw new Exception();
    } finally {
        System.out.println("method1()의 finally 블럭이 실행되었습니다.");
    }
}
```

