## 프로그램 오류



### 프로그램 에러 || 오류란 ?

프로그램이 실행 중 어떤 원인에 의해서 오작동을 하거나 비정상적으로 종료되는 경우가 있다. 이러한 결과를 초래하는 원인을 프로그램 에러 또는 오류라고 한다.

### 발생시점에 따라 다음과 같이 나눈다. 

> * `컴파일 에러` - 컴파일 시에 발생하는 에러
> * `런타임 에러` - 실행 시에 발생하는 에러
> * `논리적 에러` - 실행은 되지만, 의도와 다르게 동작하는 것



### 에러와 예외

컴파일하면 소스코드(`*.java`)에 대해 오타나 잘못된 구문, 자료형 체크 등의 기본적인 검사를 수행하여 오류가 있는지를 알려주고 성공적으로 컴파일을 마치면 비로소 `*.class`가 생성된다.

하지만 컴파일이 올바르게 되었다고 해서 실행 시에도 에러가 발생하지 않는 것은 아니다. 잠재적인 오류까지는 볼 수 없기 때문이다.

*런타임 에러를 방지하기 위해서는 프로그램의 실행 도중 발생할 수 있는 모든 경우의 수를 고려하여 이에 대한 대비를 해야한다.* 

자바에서는 실행 시 발생할 수 있는 프로그램 오류를 `에러`, `예외` 두 가지로 구분하였다.

| 구분                              | 에러 | 예외 |
| --------------------------------- | ---- | ---- |
| 복구할 수 있는가 ?                | X    | O    |
| 비정상적인 종료를 막을 수 있는가? | X    | O    |

> * `에러 (Error)` - 프로그램 코드에 의해서 수습될 수 없는 심각한 오류
> * `예외 (Exception)` - 프로그램 코드에 의해서 수습될 수 있는 다소 미약한 오류



### 예외 클래스의 계층구조

> 자바에서는 실행 시 발생할 수 있는 오류(`Exception`과 `Error`)를 클래스로 정의하였다.

모든 예외의 최고 조상은 Exception 클래스이며, 상속 계층도를 Exception 클래스부터 도식화하면 다음과 같다.

* `Exception`
  * `IOException`
  * `ClassNotFoundException`
  * `...`
  * `RuntimeException`
    * `ArithmeticException`
    * `ClassCastException`
    * `NullPointerException`
    * `...`
    * `IndexOutOfBoundsException`

도식화에서 볼 수 있듯, 예외 클래스들은 다음과 같이 두 그룹으로 나눠질 수 있다.

> 1. `Exception` 클래스와 그 자손들
>
>    : 주로 프로그래머의 실수에 의해서 발생될 수 있는 예외를 말한다.
>
> 2. `RuntimeException` 클래스와 그 자손들
>
>    : 외부의 영향으로 발생할 수 있는 것들로써, 프로그램의 사용자들의 동작에 의해서 발생하는 경우가 많다.



### 예외처리하기 - try - catch문

> *프로그램의 실행 도중에 발생하는 에러는 어쩔 수 없지만 예외는 프로그래머가 이에 대한 처리를 미리 해주어야 한다.*



#### 예외처리

* 정의 - 프로그램 실행 시 발생할 수 있는 예외에 대비한 코드를 작성하는 것.
* 목적 - 프로그램의 비정상 종료를 막고, 정상적인 실행상태를 유지하는 것.



발생한 예외를 처리하지 못하면 프로그램은 비정상적으로 종료되며, 처리되지 못한 예외는 JVM의 예외처리기(`UncaughtExceptionHandler`)가 받아서 화면에 출력한다.

예외를 처리하기 위해서는 `try - catch` 를 사용하며, 그 구조는 다음과 같다.

```java
try {
    예외가 발생할 가능성이 있는 문장들을 넣는다.
} catch(Exception1 e1) {
    // Exception1이 발생했을 경우, 이를 처리하기 위한 문장을 적는다.
} catch(Exception2 e2) {
    // Exception1이 발생했을 경우, 이를 처리하기 위한 문장을 적는다.
} catch(ExceptionN eN) {
    // ExceptionN이 발생했을 경우, 이를 처리하기 위한 문장을 적는다.
} 
```

> 하나의 try 블럭 다음에는 여러 종류의 예외를 처리할 수 있도록 하나 이상의 catch 블럭이 올 수 있으며, 이 중 발생한 예외의 종류와 일치하는 단 한 개의 catch 블럭만 수행된다. 발생한 예외의 종류와 일치하는 catch블럭이 없으면 예외는 처리되지 않는다.



* 예제 - 다중 `try - catch`문의 사용법 

```java
class Exception1 {
    public static void main(String[] args) {
        try {
            try {
            } catch (Exception e) {
            }
        } catch(Exception e) {
            try {
            } catch (Exception e) {
            }
        }
        
        try {
        } catch (Excepion e) {
            
        } // try-catch의 끝
    } // main 메서드의 끝
}
```

위처럼 여러 개의 `try-catch`문이 사용될 수 있으며, `try`블럭 또는 `catch` 블럭에 또 다른 `try-catch`문이 포함될 수 있다. 



### try - catch 문에서의 흐름

`try - catch`문에서 예외가 발생했을 때와, 발생하지 않았을 때의 흐름을 알아보자

>   *   try 블럭 내에서 예외가 발생한 경우
>       1.   발생한 예외와 일치하는 예외가 catch문에서 있는지 확인한다.
>       2.   일치하는 catch 블럭을 찾게 되면, 그 catch 블럭의 문장들을 수행하고 전체 `try - catch`문을 빠져나가서 그 다음 문장을 수행한다. 일치하는 예외가 catch에 없으면 예외는 처리되지 않는다.
>   *   try 블럭 내에서 예외가 발생하지 않은 경우
>       1.   catch 블럭을 거치지 않고 `try - catch`문을 빠져나가서 그 다음 문장들을 수행한다.

*   예제

```java
package exception;

public class ExceptionEx1 {
    public static void main(String[] args) {
        System.out.println(1);
        System.out.println(2);

        try {
            System.out.println(3);
            System.out.println(4);
        } catch (Exception e) {
            System.out.println(5);
        } // try - catch 끝
        System.out.println(6);
    } // main 끝
}
```

예외가 발생하지 않아 catch 블럭을 실행하지 않는다. 예외를 발생시켜 보자.

```java
package exception;

public class ExceptionEx2 {
    public static void main(String[] args) {
        System.out.println(1);
        System.out.println(2);
        try {
            System.out.println(3);
            System.out.println(0 / 0);
            System.out.println(4);
        } catch (ArithmeticException e) {
            System.out.println(5);
        } // try - catch 끝
        System.out.println(6);
    } // main 끝
}
```

결과는 1,2,3,5,6으로 `System.out.println(0/0)`에서 catch로 넘어가 `System.out.println(4)`는 수행되지 않는다. 그 다음엔 전체  `try - catch`문을 벗어나서 `System.out.println(6)`을 수행한다.



### 예외의 발생과 catch 블럭

catch블럭은 `()`과 `{}`으로 나눠져 있는데 `()`에는 처리하고자 하는 예외와 같은 타입의 참조변수 하나를 선언해야 한다. 예외가 발생하면 발생한 예외에 해당하는 클래스의 인스턴스가 만들어진다. ArithmeticException이 발생하면 ArithmeticException 클래스의 인스턴스가 생성된다. 

첫 번째 catch 블럭부터 차례로 내려가면서 catch 블럭의 괄호 내에 선언된 참조변수의 종류와 생성된 예외 클래스의 인스턴스에 `instanceof` 연산자를 이용해서 검사하게 되는데 검사결과가 true인 catch 블럭을 만날 때까지 검사는 계속된다.

모든 예외 클래스는 Exception 클래스의 자손이므로 catch 블럭의 괄호에 Exception 클래스를 선언해 놓으면 어떤 종류의 예외가 발생하더라도 이 catch 블럭에 의해서 처리된다.



```java
public class ExceptionEx3 {
    public static void main(String[] args) {
        System.out.println(1);
        System.out.println(2);
        try {
            System.out.println(3);
            System.out.println(0 / 0);
            System.out.println(4);
        } catch (ArithmeticException e) {
            if (e instanceof ArithmeticException) {
                System.out.println("Arithmetic Exception");
            }
        } catch (Exception e) {
            System.out.println("Exception");
        }
        System.out.println(5);
    } // main 끝
}
```

첫 번째 검사에서 일치하는 ArithmeticException이 발생하였기 때문에 두 번째 catch 블럭은 검사하지 않게 된다. 이처럼 `try - catch`문의 마지막에 Exception 클래스 타입의 참조변수를 선언한 catch 블럭을 사용하면 어떤 종류의 예외가 발생하더라도 이 catch 블럭에 의해 처리되도록 할 수 있다.



*   printStackTrace() 와 getMessage()

>   *   printStackTrace() - 예외 발생 당시의 호출 스택(Call Stack)에 있었던 메서드의 정보와 예외 메시지를 화면에 출력한다.
>   *   getMessage() - 발생한 예외클래스의 인스턴스에 저장된 메시지를 얻을 수 있다.

printStackTrace()를 사용해서 호출 스택에 대한 정보와 예외 메시지를 출력하여 예외가 발생해도 비정상적으로 종료하지 않도록 해주는 동시에 printStackTrace() 또는 getMessage()를 통해서 예외의 발생원인을 알 수 있다.



*   멀티 catch 블럭

>   JDK 1.7부터 여러 catch 블럭을 `|`기호를 이용해서 하나의 catch 블럭으로 합칠 수 있게 되었으며 이를 멀티 catch 블럭이라고 한다.
>
>   *`|`로 연결할 수 있는 예외클래스의 개수에는 제한이 없다.*

만일 멀티 catch 블럭의 `|`기호로 연결된 예외 클래스가 서로 조상과 자손의 관계에 있다면 컴파일 에러가 발생한다.

>   왜?
>
>   두 예외 클래스가 조상과 자손의 관계에 있다면 그냥 조상 클래스만 써주는 것과 똑같기 때문이다. 불필요한 코드는 제거하라는 의미에서 에러가 발생한다.

그리고 멀티 catch는 하나의 catch 블럭으로 여러 예외를 처리하는 것이기 때문에 발생한 예외를 멀티 catch 블럭으로 처리하게 되었을 때 멀티 catch 블럭 내에서는 실제로 어떤 예외가 발생한 것인지 알 수 없다. 그래서 참조변수로 멀티 catch 블럭에 `|` 기호로 연결된 예외 클래스들의 공통 분모인 조상 예외 클래스에 선언된 멤버만 사용할 수 있다.
